Workbook
Name coef_18_0: '[1]18 anos'!$V$13
Name coef_18_1: '[1]18 anos'!$V$12
Name coef_18_2: '[1]18 anos'!$V$11
Name coef_18_3: '[1]18 anos'!$V$10
Name coef_19_0: '[1]19 anos'!$Y$16
Name coef_19_1: '[1]19 anos'!$Y$15
Name coef_19_2: '[1]19 anos'!$Y$14
Name coef_19_3: '[1]19 anos'!$Y$13
Name coef_20_0: '[1]20 anos'!$X$15
Name coef_20_1: '[1]20 anos'!$X$14
Name coef_20_2: '[1]20 anos'!$X$13
Name coef_20_3: '[1]20 anos'!$X$12

Sheet DADOS BRUTOS
A1: Idade | B1: GRL | C1: Valor de Mercado 1 | D1: Valor de Mercado 2
A2: 18 | B2: 40 | C2: 4.5 | D2: =B2^4*CURVAS!$B$3+B2^3*CURVAS!$C$3+B2^2*CURVAS!$D$3+B2^1*CURVAS!$E$3+B2^0*CURVAS!$F$3 -> 4.51978
A3: 18 | B3: 41 | C3: 4.6 | D3: =B3^4*CURVAS!$B$3+B3^3*CURVAS!$C$3+B3^2*CURVAS!$D$3+B3^1*CURVAS!$E$3+B3^0*CURVAS!$F$3 -> 4.6008141
A4: 18 | B4: 42 | C4: 4.63 | D4: =B4^4*CURVAS!$B$3+B4^3*CURVAS!$C$3+B4^2*CURVAS!$D$3+B4^1*CURVAS!$E$3+B4^0*CURVAS!$F$3 -> 4.6831055
A5: 18 | B5: 43 | C5: 4.67 | D5: =B5^4*CURVAS!$B$3+B5^3*CURVAS!$C$3+B5^2*CURVAS!$D$3+B5^1*CURVAS!$E$3+B5^0*CURVAS!$F$3 -> 4.766662
A6: 18 | B6: 44 | C6: 4.88 | D6: =B6^4*CURVAS!$B$3+B6^3*CURVAS!$C$3+B6^2*CURVAS!$D$3+B6^1*CURVAS!$E$3+B6^0*CURVAS!$F$3 -> 4.8514915
A7: 18 | B7: 45 | C7: 4.92 | D7: =B7^4*CURVAS!$B$3+B7^3*CURVAS!$C$3+B7^2*CURVAS!$D$3+B7^1*CURVAS!$E$3+B7^0*CURVAS!$F$3 -> 4.9376019
A8: 18 | B8: 46 | C8: 4.96 | D8: =B8^4*CURVAS!$B$3+B8^3*CURVAS!$C$3+B8^2*CURVAS!$D$3+B8^1*CURVAS!$E$3+B8^0*CURVAS!$F$3 -> 5.0250012
A9: 18 | B9: 47 | C9: 5 | D9: =B9^4*CURVAS!$B$3+B9^3*CURVAS!$C$3+B9^2*CURVAS!$D$3+B9^1*CURVAS!$E$3+B9^0*CURVAS!$F$3 -> 5.1136974
A10: 18 | B10: 48 | C10: 5.2 | D10: =B10^4*CURVAS!$B$3+B10^3*CURVAS!$C$3+B10^2*CURVAS!$D$3+B10^1*CURVAS!$E$3+B10^0*CURVAS!$F$3 -> 5.2036988
A11: 18 | B11: 49 | C11: 5.3 | D11: =B11^4*CURVAS!$B$3+B11^3*CURVAS!$C$3+B11^2*CURVAS!$D$3+B11^1*CURVAS!$E$3+B11^0*CURVAS!$F$3 -> 5.2950136
A12: 18 | B12: 50 | C12: 5.35 | D12: =B12^4*CURVAS!$B$3+B12^3*CURVAS!$C$3+B12^2*CURVAS!$D$3+B12^1*CURVAS!$E$3+B12^0*CURVAS!$F$3 -> 5.38765
A13: 18 | B13: 51 | C13: 5.5 | D13: =B13^4*CURVAS!$B$3+B13^3*CURVAS!$C$3+B13^2*CURVAS!$D$3+B13^1*CURVAS!$E$3+B13^0*CURVAS!$F$3 -> 5.4816164
... A212: 18 | B212: 250 | C212: 67 | D212: =B212^4*CURVAS!$B$3+B212^3*CURVAS!$C$3+B212^2*CURVAS!$D$3+B212^1*CURVAS!$E$3+B212^0*CURVAS!$F$3 -> 66.64765
A213: 19 | B213: 40 | C213: 3.63 | D213: =B2^4*CURVAS!$B$4+B2^3*CURVAS!$C$4+B2^2*CURVAS!$D$4+B2^1*CURVAS!$E$4+B2^0*CURVAS!$F$4 -> 3.58054
A214: 19 | B214: 41 | C214: 3.66 | D214: =B3^4*CURVAS!$B$4+B3^3*CURVAS!$C$4+B3^2*CURVAS!$D$4+B3^1*CURVAS!$E$4+B3^0*CURVAS!$F$4 -> 3.6468714
A215: 19 | B215: 42 | C215: 3.69 | D215: =B4^4*CURVAS!$B$4+B4^3*CURVAS!$C$4+B4^2*CURVAS!$D$4+B4^1*CURVAS!$E$4+B4^0*CURVAS!$F$4 -> 3.714382
A216: 19 | B216: 43 | C216: 3.73 | D216: =B5^4*CURVAS!$B$4+B5^3*CURVAS!$C$4+B5^2*CURVAS!$D$4+B5^1*CURVAS!$E$4+B5^0*CURVAS!$F$4 -> 3.783078
A217: 19 | B217: 44 | C217: 3.915 | D217: =B6^4*CURVAS!$B$4+B6^3*CURVAS!$C$4+B6^2*CURVAS!$D$4+B6^1*CURVAS!$E$4+B6^0*CURVAS!$F$4 -> 3.852966
A218: 19 | B218: 45 | C218: 3.95 | D218: =B7^4*CURVAS!$B$4+B7^3*CURVAS!$C$4+B7^2*CURVAS!$D$4+B7^1*CURVAS!$E$4+B7^0*CURVAS!$F$4 -> 3.9240525
A219: 19 | B219: 46 | C219: 4 | D219: =B8^4*CURVAS!$B$4+B8^3*CURVAS!$C$4+B8^2*CURVAS!$D$4+B8^1*CURVAS!$E$4+B8^0*CURVAS!$F$4 -> 3.9963442
A220: 19 | B220: 47 | C220: 4.02 | D220: =B9^4*CURVAS!$B$4+B9^3*CURVAS!$C$4+B9^2*CURVAS!$D$4+B9^1*CURVAS!$E$4+B9^0*CURVAS!$F$4 -> 4.0698479
A221: 19 | B221: 48 | C221: 4.02 | D221: =B10^4*CURVAS!$B$4+B10^3*CURVAS!$C$4+B10^2*CURVAS!$D$4+B10^1*CURVAS!$E$4+B10^0*CURVAS!$F$4 -> 4.1445705
A222: 19 | B222: 49 | C222: 4.24 | D222: =B11^4*CURVAS!$B$4+B11^3*CURVAS!$C$4+B11^2*CURVAS!$D$4+B11^1*CURVAS!$E$4+B11^0*CURVAS!$F$4 -> 4.2205188
A223: 19 | B223: 50 | C223: 4.3 | D223: =B12^4*CURVAS!$B$4+B12^3*CURVAS!$C$4+B12^2*CURVAS!$D$4+B12^1*CURVAS!$E$4+B12^0*CURVAS!$F$4 -> 4.2977
A224: 19 | B224: 51 | C224: 4.34 | D224: =B13^4*CURVAS!$B$4+B13^3*CURVAS!$C$4+B13^2*CURVAS!$D$4+B13^1*CURVAS!$E$4+B13^0*CURVAS!$F$4 -> 4.3761212
... A423: 19 | B423: 250 | C423: 59.5 | D423: =B212^4*CURVAS!$B$4+B212^3*CURVAS!$C$4+B212^2*CURVAS!$D$4+B212^1*CURVAS!$E$4+B212^0*CURVAS!$F$4 -> 60.6577
A424: 20 | B424: 40 | C424: =C213*0.7 -> 2.541 | D424: =B2^4*CURVAS!$B$5+B2^3*CURVAS!$C$5+B2^2*CURVAS!$D$5+B2^1*CURVAS!$E$5+B2^0*CURVAS!$F$5 -> 2.646304
A425: 20 | B425: 41 | C425: =C214*0.7 -> 2.562 | D425: =B3^4*CURVAS!$B$5+B3^3*CURVAS!$C$5+B3^2*CURVAS!$D$5+B3^1*CURVAS!$E$5+B3^0*CURVAS!$F$5 -> 2.7117852
A426: 20 | B426: 42 | C426: =C215*0.7 -> 2.583 | D426: =B4^4*CURVAS!$B$5+B4^3*CURVAS!$C$5+B4^2*CURVAS!$D$5+B4^1*CURVAS!$E$5+B4^0*CURVAS!$F$5 -> 2.7779765
A427: 20 | B427: 43 | C427: =C216*0.7 -> 2.611 | D427: =B5^4*CURVAS!$B$5+B5^3*CURVAS!$C$5+B5^2*CURVAS!$D$5+B5^1*CURVAS!$E$5+B5^0*CURVAS!$F$5 -> 2.8448909
A428: 20 | B428: 44 | C428: =C217*0.7 -> 2.7405 | D428: =B6^4*CURVAS!$B$5+B6^3*CURVAS!$C$5+B6^2*CURVAS!$D$5+B6^1*CURVAS!$E$5+B6^0*CURVAS!$F$5 -> 2.9125413
A429: 20 | B429: 45 | C429: =C218*0.7 -> 2.765 | D429: =B7^4*CURVAS!$B$5+B7^3*CURVAS!$C$5+B7^2*CURVAS!$D$5+B7^1*CURVAS!$E$5+B7^0*CURVAS!$F$5 -> 2.9809406
A430: 20 | B430: 46 | C430: 3.15 | D430: =B8^4*CURVAS!$B$5+B8^3*CURVAS!$C$5+B8^2*CURVAS!$D$5+B8^1*CURVAS!$E$5+B8^0*CURVAS!$F$5 -> 3.0501017
A431: 20 | B431: 47 | C431: 3.18 | D431: =B9^4*CURVAS!$B$5+B9^3*CURVAS!$C$5+B9^2*CURVAS!$D$5+B9^1*CURVAS!$E$5+B9^0*CURVAS!$F$5 -> 3.1200377
A432: 20 | B432: 48 | C432: 3.34 | D432: =B10^4*CURVAS!$B$5+B10^3*CURVAS!$C$5+B10^2*CURVAS!$D$5+B10^1*CURVAS!$E$5+B10^0*CURVAS!$F$5 -> 3.1907616
A433: 20 | B433: 49 | C433: 3.39 | D433: =B11^4*CURVAS!$B$5+B11^3*CURVAS!$C$5+B11^2*CURVAS!$D$5+B11^1*CURVAS!$E$5+B11^0*CURVAS!$F$5 -> 3.2622863
A434: 20 | B434: 50 | C434: 3.43 | D434: =B12^4*CURVAS!$B$5+B12^3*CURVAS!$C$5+B12^2*CURVAS!$D$5+B12^1*CURVAS!$E$5+B12^0*CURVAS!$F$5 -> 3.334625
A435: 20 | B435: 51 | C435: 3.44 | D435: =B13^4*CURVAS!$B$5+B13^3*CURVAS!$C$5+B13^2*CURVAS!$D$5+B13^1*CURVAS!$E$5+B13^0*CURVAS!$F$5 -> 3.4077907
A436: 20 | B436: 52 | C436: 3.63 | D436: =B14^4*CURVAS!$B$5+B14^3*CURVAS!$C$5+B14^2*CURVAS!$D$5+B14^1*CURVAS!$E$5+B14^0*CURVAS!$F$5 -> 3.4817965
...

Sheet CURVAS
A1: Idade | B1: Coeficientes
B2: 4 | C2: 3 | D2: 2 | E2: 1 | F2: 0
A3: 18 | B3: 3e-09 | C3: 8e-07 | D3: 0.0005 | E3: 0.0358 | F3: 2.2289
A4: 19 | B4: 4e-09 | C4: 4e-07 | D4: 0.0005 | E4: 0.0228 | F4: 1.8327
A5: 20 | B5: 9e-10 | C5: 2e-06 | D5: 0.0001 | E5: 0.0473 | F5: 0.464
A6: 21 | B6: 5e-10 | C6: 2e-06 | D6: 1e-05 | E6: 0.0455 | F6: 0.0545

Sheet SIMULADOR
A1: ⚽ TOP ELEVEN MARKET ANALYZER
A4: Simulador de Leilão para jogadores 18-21 anos
B6: DADOS DO JOGADOR | L6: RESULTADOS
B7: NÍVEL DA CONTA | F7: 7 | L7: NÍVEL DA CONTA BASE | P7: 5
B8: GRL | F8: 50 | L8: GLR DA CONTA BASE | P8: =+F8-(5-F7)*20 -> 90
B9: VALOR DE MERCADO (M) | F9: 7 | L9: PREÇO JUSTO (M) | P9: =INDEX('DADOS BRUTOS'!D:D,2+((F10-18)*211)+(P8-40)) -> 7.048049
B10: IDADE DO JOGADOR (ANOS) | F10: 20 | L10: SCORE | P10: =F9/P9 -> 0.99318265
A12: CLASSIFICAÇÃO: | H12: =IF(P10>=98%,"FENÔMENO",IF(P10>=95%,"EXCELENTE",IF(P10>=90%,"ÓTIMO",IF(P10>=80%,"BOM",IF(P10>=60%,"NORMAL","RUIM"))))) -> FENÔMENO | O12: =IF(H12="FENÔMENO","GASTE AGORA!!",IF(H12="EXCELENTE","GASTE AGORA!!",IF(H12="ÓTIMO","BOA!!","TESTE OUTRO JOGADOR"))) -> GASTE AGORA!!
A23: Desenvolvido por Thallyson Souza
